Workbook

Sheet Журнал Работ
A1: Дата | B1: Смена день/ночь | C1: Здание | D1: Кол-во испол-ей, эл.монт. | E1: Наименование | F1: Объём выполненной работы | G1: Помещение, Отметка | H1: Раздел/Примечание/прочие работы
A2: 46097 | B2: День | C2: 406/1 | D2: 2 | E2: Монтаж полосы заземления 25x4, м | F2: 18 | G2: 111
C3: 406/1 | E3: Монтаж скобы-держателя ND2312, шт | F3: 30
A4: 46097 | B4: День | C4: 406/1 | D4: 3 | E4: Монтаж полосы заземления 25x4, м | F4: 48 | G4: 101
C5: 406/1 | E5: Монтаж скобы-держателя ND2312, шт | F5: 108
A6: 46098 | B6: День | C6: 406/1 | D6: 2 | E6: Монтаж полосы заземления 25x4, м | F6: 30 | G6: 111
C7: 406/1 | E7: Монтаж скобы-держателя ND2312, шт | F7: 68
A8: 46098 | B8: День | C8: 406/3 | D8: 3 | E8: Монтаж полосы заземления 25x4, м | F8: 18 | G8: 101
C9: 406/3 | E9: Монтаж скобы-держателя ND2312, шт | F9: 30
A10: 46099 | B10: День | C10: 406/3 | D10: 3 | E10: Монтаж полосы заземления 25x4, м | F10: 30 | G10: 101
C11: 406/3 | E11: Монтаж скобы-держателя ND2312, шт | F11: 68
A12: 46099 | B12: День | C12: 406/3 | D12: 4 | E12: Монтаж полосы заземления 25x4, м | F12: 30 | G12: 111
C13: 406/3 | E13: Монтаж скобы-держателя ND2312, шт | F13: 60
A14: 46100 | B14: День | C14: 406/1 | D14: 4 | E14: Монтаж консоли 300 мм, шт | F14: 6 | H14: Не было 2 часа электропитания
C15: 406/1 | E15: Монтаж консоли 400 мм, шт | F15: 15
C16: 406/1 | E16: Монтаж лотка перф. 200х80, м | F16: 6
A17: 46100 | B17: День | C17: 406/1 | D17: 2 | E17: Комплектация и доставка материала со склада | F17: —
A18: 46101 | B18: День | C18: 406/1 | D18: 10 | E18: Монтаж шпилек М8, шт | F18: 40 | G18: 101, 111, 116, +9000
C19: 406/1 | E19: Монтаж полосы заземления, м | F19: 18
C20: 406/1 | E20: Монтаж скобы-держателя ND2312, шт | F20: 30
A21: 46102 | B21: День | C21: 406/1 | D21: 11 | E21: Монтаж шпилек М8, шт | F21: 40 | G21: 116, +9500
C22: 406/1 | E22: Монтаж консоли 400 мм, шт | F22: 12
C23: 406/1 | E23: Монтаж полосы заземления 25x4, м | F23: 30
C24: 406/1 | E24: Монтаж скобы-держателя ND2312, шт | F24: 68
A25: 46102 | B25: День | C25: 450 | D25: 1 | E25: Комплектация и доставка материала со склада | F25: —
A26: 46102 | B26: День | C26: 450 | D26: 5 | E26: Монтаж полосы заземления 25x4, м | F26: 20
C27: 450 | E27: Монтаж скобы-держателя ND2312, шт | F27: 20
A28: 46103 | B28: День | C28: 406/1 | D28: 14 | E28: Разметка отверстий шт | F28: 5 | G28: 112, 111, +9500
C29: 406/1 | E29: Монтаж консоли 400 мм, шт | F29: 15
C30: 406/1 | E30: Монтаж полосы заземления 25x4, м | F30: 24
C31: 406/1 | E31: Монтаж скобы-держателя ND2312, шт | F31: 48
C32: 406/1 | E32: Монтаж шпилек М8, шт | F32: 175
C33: 406/1 | E33: Заготовка гильзопакетов | F33: 50
A34: 46103 | B34: День | C34: 450 | D34: 7 | E34: Монтаж полосы заземления 25x4, м | F34: 60
C35: 450 | E35: Монтаж скобы-держателя ND2312, шт | F35: 60
A36: 46104 | B36: День | C36: 406/1 | D36: 14 | E36: Разметка отверстий шт | F36: 5
C37: 406/1 | E37: Монтаж консоли, шт | F37: 15
C38: 406/1 | E38: Монтаж полосы заземления, м | F38: 24
C39: 406/1 | E39: Монтаж скобы-держателя ND2312, шт | F39: 48 | H39: Сборка и разборка лесов. Продолжительность времени 60 минут
C40: 406/1 | E40: Монтаж шпилек М8, шт | F40: 175
...

Sheet Общий Объём работ
A1: Общий отчет выполненых работ ООО "КСИ" | E1: =TODAY() -> 46195
A2: Тип работы | B2: Наименование работ | C2: 406/1 | D2: 406/2 | E2: Заложено по спец. | F2: Остаток 406/1 | G2: Остаток 406/2 | H2: Примечание | I2: Наличие на складе | J2: ЭМ | K2: ЭО
B3: Изготовление отверстий, шт | C3: =SUMIFS('Журнал Работ'!F:F,'Журнал Работ'!E:E,B3,'Журнал Работ'!C:C,$C$2) -> 4 | D3: =SUMIFS('Журнал Работ'!F:F,'Журнал Работ'!E:E,B3,'Журнал Работ'!C:C,$D$2) -> 222 | H3: прочие работы
B4: Бурение под гильзы/гильзо-пакеты | C4: =SUMIFS('Журнал Работ'!F:F,'Журнал Работ'!E:E,B4,'Журнал Работ'!C:C,$C$2) -> 8 | D4: =SUMIFS('Журнал Работ'!F:F,'Журнал Работ'!E:E,B4,'Журнал Работ'!C:C,$D$2) -> 2 | H4: прочие работы
B5: Выгрузка щита | C5: =SUMIFS('Журнал Работ'!F:F,'Журнал Работ'!E:E,B5,'Журнал Работ'!C:C,$C$2) -> 2 | D5: =SUMIFS('Журнал Работ'!F:F,'Журнал Работ'!E:E,B5,'Журнал Работ'!C:C,$D$2) -> 0 | H5: прочие работы
B6: Выравнивание и крепление лотков | C6: =SUMIFS('Журнал Работ'!F:F,'Журнал Работ'!E:E,B6,'Журнал Работ'!C:C,$C$2) -> 0 | D6: =SUMIFS('Журнал Работ'!F:F,'Журнал Работ'!E:E,B6,'Журнал Работ'!C:C,$D$2) -> 0 | H6: прочие работы
B7: Гереметизация отверстий гильзо-пакетов | C7: =SUMIFS('Журнал Работ'!F:F,'Журнал Работ'!E:E,B7,'Журнал Работ'!C:C,$C$2) -> 0 | D7: =SUMIFS('Журнал Работ'!F:F,'Журнал Работ'!E:E,B7,'Журнал Работ'!C:C,$D$2) -> 0 | H7: прочие работы
B8: Демонтаж временых консолей, шт | C8: =SUMIFS('Журнал Работ'!F:F,'Журнал Работ'!E:E,B8,'Журнал Работ'!C:C,$C$2) -> 0 | D8: =SUMIFS('Журнал Работ'!F:F,'Журнал Работ'!E:E,B8,'Журнал Работ'!C:C,$D$2) -> 13 | H8: прочие работы
B9: Демонтаж лотка лест. 300х80, м | C9: =SUMIFS('Журнал Работ'!F:F,'Журнал Работ'!E:E,B9,'Журнал Работ'!C:C,$C$2) -> 0 | D9: =SUMIFS('Журнал Работ'!F:F,'Журнал Работ'!E:E,B9,'Журнал Работ'!C:C,$D$2) -> 8.5 | H9: прочие работы
B10: Демонтаж лотка лест. 400х80, м | C10: =SUMIFS('Журнал Работ'!F:F,'Журнал Работ'!E:E,B10,'Журнал Работ'!C:C,$C$2) -> 3 | D10: =SUMIFS('Журнал Работ'!F:F,'Журнал Работ'!E:E,B10,'Журнал Работ'!C:C,$D$2) -> 0 | H10: прочие работы
B11: Демонтаж РК, шт | C11: =SUMIFS('Журнал Работ'!F:F,'Журнал Работ'!E:E,B11,'Журнал Работ'!C:C,$C$2) -> 5 | D11: =SUMIFS('Журнал Работ'!F:F,'Журнал Работ'!E:E,B11,'Журнал Работ'!C:C,$D$2) -> 0 | H11: прочие работы
B12: Демонтаж трубы ВГП Дн20, м | C12: =SUMIFS('Журнал Работ'!F:F,'Журнал Работ'!E:E,B12,'Журнал Работ'!C:C,$C$2) -> 20 | D12: =SUMIFS('Журнал Работ'!F:F,'Журнал Работ'!E:E,B12,'Журнал Работ'!C:C,$D$2) -> 0 | H12: прочие работы
B13: Демонтаж/монтаж гофры Дн20 | C13: =SUMIFS('Журнал Работ'!F:F,'Журнал Работ'!E:E,B13,'Журнал Работ'!C:C,$C$2) -> 34 | D13: =SUMIFS('Журнал Работ'!F:F,'Журнал Работ'!E:E,B13,'Журнал Работ'!C:C,$D$2) -> 0 | H13: прочие работы
B14: Демонтаж/монтаж кабеля, м | C14: =SUMIFS('Журнал Работ'!F:F,'Журнал Работ'!E:E,B14,'Журнал Работ'!C:C,$C$2) -> 54 | D14: =SUMIFS('Журнал Работ'!F:F,'Журнал Работ'!E:E,B14,'Журнал Работ'!C:C,$D$2) -> 5 | H14: прочие работы
... B30: Комплектация и заготовка материала | C30: =SUMIFS('Журнал Работ'!F:F,'Журнал Работ'!E:E,B30,'Журнал Работ'!C:C,$C$2) -> 0 | D30: =SUMIFS('Журнал Работ'!F:F,'Журнал Работ'!E:E,B30,'Журнал Работ'!C:C,$D$2) -> 0 | H30: прочие работы
B31: Монтаж анкерного болта шт | C31: =SUMIFS('Журнал Работ'!F:F,'Журнал Работ'!E:E,B31,'Журнал Работ'!C:C,$C$2) -> 38 | D31: =SUMIFS('Журнал Работ'!F:F,'Журнал Работ'!E:E,B31,'Журнал Работ'!C:C,$D$2) -> 0
B32: Монтаж БАП, шт | C32: =SUMIFS('Журнал Работ'!F:F,'Журнал Работ'!E:E,B32,'Журнал Работ'!C:C,$C$2) -> 96 | D32: =SUMIFS('Журнал Работ'!F:F,'Журнал Работ'!E:E,B32,'Журнал Работ'!C:C,$D$2) -> 58
B33: Монтаж временных консолей шт | C33: =SUMIFS('Журнал Работ'!F:F,'Журнал Работ'!E:E,B33,'Журнал Работ'!C:C,$C$2) -> 8 | D33: =SUMIFS('Журнал Работ'!F:F,'Журнал Работ'!E:E,B33,'Журнал Работ'!C:C,$D$2) -> 13 | H33: прочие работы
B34: Монтаж гильз/гильзопакетов | C34: =SUMIFS('Журнал Работ'!F:F,'Журнал Работ'!E:E,B34,'Журнал Работ'!C:C,$C$2) -> 29 | D34: =SUMIFS('Журнал Работ'!F:F,'Журнал Работ'!E:E,B34,'Журнал Работ'!C:C,$D$2) -> 18 | H34: прочие работы
B35: Монтаж гофры Дн20, м | C35: =SUMIFS('Журнал Работ'!F:F,'Журнал Работ'!E:E,B35,'Журнал Работ'!C:C,$C$2) -> 2324 | D35: =SUMIFS('Журнал Работ'!F:F,'Журнал Работ'!E:E,B35,'Журнал Работ'!C:C,$D$2) -> 650.5
B36: Монтаж гофры Дн25, м | C36: =SUMIFS('Журнал Работ'!F:F,'Журнал Работ'!E:E,B36,'Журнал Работ'!C:C,$C$2) -> 30 | D36: =SUMIFS('Журнал Работ'!F:F,'Журнал Работ'!E:E,B36,'Журнал Работ'!C:C,$D$2) -> 0
B37: Монтаж заземления лотка IEK 200мм D=6мм 4мм.кв, шт | C37: =SUMIFS('Журнал Работ'!F:F,'Журнал Работ'!E:E,B37,'Журнал Работ'!C:C,$C$2) -> 245 | D37: =SUMIFS('Журнал Работ'!F:F,'Журнал Работ'!E:E,B37,'Журнал Работ'!C:C,$D$2) -> 218
B38: Монтаж заземлителя уголок верт. 50x50х5 L3000, шт | C38: =SUMIFS('Журнал Работ'!F:F,'Журнал Работ'!E:E,B38,'Журнал Работ'!C:C,$C$2) -> 35 | D38: =SUMIFS('Журнал Работ'!F:F,'Журнал Работ'!E:E,B38,'Журнал Работ'!C:C,$D$2) -> 37
A39: Кабель | B39: Монтаж кабеля ВВГнг(А)-LS 4х2,5, м | C39: =SUMIFS('Журнал Работ'!F:F,'Журнал Работ'!E:E,B39,'Журнал Работ'!C:C,$C$2) -> 1505 | D39: =SUMIFS('Журнал Работ'!F:F,'Журнал Работ'!E:E,B39,'Журнал Работ'!C:C,$D$2) -> 100 | E39: 2075 | F39: =E39-Таблица1[[#This Row],[406/1]] -> 570 | G39: =E39-Таблица1[[#This Row],[406/2]] -> 1975 | J39: 128
A40: Кабель | B40: Монтаж кабеля ВВГнг(А)-FRLS 4х2,5, м | C40: =SUMIFS('Журнал Работ'!F:F,'Журнал Работ'!E:E,B40,'Журнал Работ'!C:C,$C$2) -> 249 | D40: =SUMIFS('Журнал Работ'!F:F,'Журнал Работ'!E:E,B40,'Журнал Работ'!C:C,$D$2) -> 25 | F40: =E40-Таблица1[[#This Row],[406/1]] -> -249 | G40: =E40-Таблица1[[#This Row],[406/2]] -> -25 | J40: 129
A41: Кабель | B41: Монтаж кабеля ВВГнг(А)-FRLS 3х1,5, м | C41: =SUMIFS('Журнал Работ'!F:F,'Журнал Работ'!E:E,B41,'Журнал Работ'!C:C,$C$2) -> 792 | D41: =SUMIFS('Журнал Работ'!F:F,'Журнал Работ'!E:E,B41,'Журнал Работ'!C:C,$D$2) -> 57 | E41: =J41+K41 -> 1457 | F41: =E41-Таблица1[[#This Row],[406/1]] -> 665 | G41: =E41-Таблица1[[#This Row],[406/2]] -> 1400 | J41: 1132 | K41: 325
A42: Кабель | B42: Монтаж кабеля ВВГнг(А)-FRLST 3х2,5, м | C42: =SUMIFS('Журнал Работ'!F:F,'Журнал Работ'!E:E,B42,'Журнал Работ'!C:C,$C$2) -> 31 | D42: =SUMIFS('Журнал Работ'!F:F,'Журнал Работ'!E:E,B42,'Журнал Работ'!C:C,$D$2) -> 0
A43: Кабель | B43: Монтаж кабеля ВВГнг(А)-FRLS 4х1,5, м | C43: =SUMIFS('Журнал Работ'!F:F,'Журнал Работ'!E:E,B43,'Журнал Работ'!C:C,$C$2) -> 1471 | D43: =SUMIFS('Журнал Работ'!F:F,'Журнал Работ'!E:E,B43,'Журнал Работ'!C:C,$D$2) -> 168 | E43: =J43+K43 -> 1151 | F43: =E43-Таблица1[[#This Row],[406/1]] -> -320 | G43: =E43-Таблица1[[#This Row],[406/2]] -> 983 | K43: 1151
A44: Кабель | B44: Монтаж кабеля ВВГнг(А)-LS 3х1,5, м | C44: =SUMIFS('Журнал Работ'!F:F,'Журнал Работ'!E:E,B44,'Журнал Работ'!C:C,$C$2) -> 2499 | D44: =SUMIFS('Журнал Работ'!F:F,'Журнал Работ'!E:E,B44,'Журнал Работ'!C:C,$D$2) -> 615.5 | E44: =J44+K44 -> 649 | F44: =E44-Таблица1[[#This Row],[406/1]] -> -1850 | G44: =E44-Таблица1[[#This Row],[406/2]] -> 33.5 | K44: 649
A45: Кабель | B45: Монтаж кабеля ВВГнг(А)-LS 3х2,5, м | C45: =SUMIFS('Журнал Работ'!F:F,'Журнал Работ'!E:E,B45,'Журнал Работ'!C:C,$C$2) -> 359 | D45: =SUMIFS('Журнал Работ'!F:F,'Журнал Работ'!E:E,B45,'Журнал Работ'!C:C,$D$2) -> 23 | E45: =J45+K45 -> 288 | F45: =E45-Таблица1[[#This Row],[406/1]] -> -71 | G45: =E45-Таблица1[[#This Row],[406/2]] -> 265 | J45: 86 | K45: 202
A46: Кабель | B46: Монтаж кабеля КВВГнг(А)-LS 4х1,5, м | C46: =SUMIFS('Журнал Работ'!F:F,'Журнал Работ'!E:E,B46,'Журнал Работ'!C:C,$C$2) -> 622 | D46: =SUMIFS('Журнал Работ'!F:F,'Журнал Работ'!E:E,B46,'Журнал Работ'!C:C,$D$2) -> 0 | E46: 1151 | F46: =E46-Таблица1[[#This Row],[406/1]] -> 529 | G46: =E46-Таблица1[[#This Row],[406/2]] -> 1151 | H46: всесто КВВГнг(А)-LS 3х1,5, м
A47: Кабель | B47: Монтаж кабеля КВВГнг(А)-LS 7х1,5, м | C47: =SUMIFS('Журнал Работ'!F:F,'Журнал Работ'!E:E,B47,'Журнал Работ'!C:C,$C$2) -> 585 | D47: =SUMIFS('Журнал Работ'!F:F,'Журнал Работ'!E:E,B47,'Журнал Работ'!C:C,$D$2) -> 153 | F47: =E47-Таблица1[[#This Row],[406/1]] -> -585 | G47: =E47-Таблица1[[#This Row],[406/2]] -> -153
A48: Кабель | B48: Монтаж кабеля ВВГнг(А)-LS 3х4, м | C48: =SUMIFS('Журнал Работ'!F:F,'Журнал Работ'!E:E,B48,'Журнал Работ'!C:C,$C$2) -> 22 | D48: =SUMIFS('Журнал Работ'!F:F,'Журнал Работ'!E:E,B48,'Журнал Работ'!C:C,$D$2) -> 0 | F48: =E48-Таблица1[[#This Row],[406/1]] -> -22 | G48: =E48-Таблица1[[#This Row],[406/2]] -> 0 | H48: убрали с проекта
A49: Кабель | B49: Монтаж кабеля ВВГнг(А)-LS 5х1,5, м | C49: =SUMIFS('Журнал Работ'!F:F,'Журнал Работ'!E:E,B49,'Журнал Работ'!C:C,$C$2) -> 295 | D49: =SUMIFS('Журнал Работ'!F:F,'Журнал Работ'!E:E,B49,'Журнал Работ'!C:C,$D$2) -> 140 | E49: =J49+K49 -> 889 | F49: =E49-Таблица1[[#This Row],[406/1]] -> 594 | G49: =E49-Таблица1[[#This Row],[406/2]] -> 749 | J49: 749 | K49: 140
A50: Кабель | B50: Монтаж кабеля ВВГнг(А)-LS 5х2,5, м | C50: =SUMIFS('Журнал Работ'!F:F,'Журнал Работ'!E:E,B50,'Журнал Работ'!C:C,$C$2) -> 769 | D50: =SUMIFS('Журнал Работ'!F:F,'Журнал Работ'!E:E,B50,'Журнал Работ'!C:C,$D$2) -> 191 | E50: =J50+K50 -> 1123 | F50: =E50-Таблица1[[#This Row],[406/1]] -> 354 | G50: =E50-Таблица1[[#This Row],[406/2]] -> 932 | J50: 948 | K50: 175
A51: Кабель | B51: Монтаж кабеля ВВГнг(А)-LS 5х4, м | C51: =SUMIFS('Журнал Работ'!F:F,'Журнал Работ'!E:E,B51,'Журнал Работ'!C:C,$C$2) -> 1185 | D51: =SUMIFS('Журнал Работ'!F:F,'Журнал Работ'!E:E,B51,'Журнал Работ'!C:C,$D$2) -> 0 | E51: 1110 | F51: =E51-Таблица1[[#This Row],[406/1]] -> -75 | G51: =E51-Таблица1[[#This Row],[406/2]] -> 1110
A52: Кабель | B52: Монтаж кабеля ВВГнг(А)-LS 5х6, м | C52: =SUMIFS('Журнал Работ'!F:F,'Журнал Работ'!E:E,B52,'Журнал Работ'!C:C,$C$2) -> 44 | D52: =SUMIFS('Журнал Работ'!F:F,'Журнал Работ'!E:E,B52,'Журнал Работ'!C:C,$D$2) -> 0 | E52: =J52+K52 -> 42 | F52: =E52-Таблица1[[#This Row],[406/1]] -> -2 | G52: =E52-Таблица1[[#This Row],[406/2]] -> 42 | J52: 42
A53: Кабель | B53: Монтаж кабеля ВВГнг(А)-LS 5х16, м | C53: =SUMIFS('Журнал Работ'!F:F,'Журнал Работ'!E:E,B53,'Журнал Работ'!C:C,$C$2) -> 185 | D53: =SUMIFS('Журнал Работ'!F:F,'Журнал Работ'!E:E,B53,'Журнал Работ'!C:C,$D$2) -> 0 | E53: 200 | F53: =E53-Таблица1[[#This Row],[406/1]] -> 15 | G53: =E53-Таблица1[[#This Row],[406/2]] -> 200
A54: Кабель | B54: Монтаж кабеля ВВГнг(А)-LS 5х25, м | C54: =SUMIFS('Журнал Работ'!F:F,'Журнал Работ'!E:E,B54,'Журнал Работ'!C:C,$C$2) -> 33 | D54: =SUMIFS('Журнал Работ'!F:F,'Журнал Работ'!E:E,B54,'Журнал Работ'!C:C,$D$2) -> 0 | E54: 200 | F54: =E54-Таблица1[[#This Row],[406/1]] -> 167 | G54: =E54-Таблица1[[#This Row],[406/2]] -> 200
A55: Кабель | B55: Монтаж кабеля ВВГнг(А)-LS 5х35, м | C55: =SUMIFS('Журнал Работ'!F:F,'Журнал Работ'!E:E,B55,'Журнал Работ'!C:C,$C$2) -> 239 | D55: =SUMIFS('Журнал Работ'!F:F,'Журнал Работ'!E:E,B55,'Журнал Работ'!C:C,$D$2) -> 0
...

Sheet Карткий отчет
A1: Краткий отчет | B1: ООО "КСИ" | D1: =+TODAY()+1 -> 46196
A2: 406/1 | B2: ед.изм. | C2: Заложено | D2: Выполнено | E2: Остаток | F2: % выполненияя | G2: % осталось
A3: Оборудование | B3: шт | C3: 30 | D3: =SUMIFS('Общий Объём работ'!C:C,'Общий Объём работ'!A:A,A3) -> 27 | E3: =C3-D3 -> 3 | F3: =D3/C3 -> 0.9 | G3: =E3/C3 -> 0.1
A4: Кабель | B4: м | C4: 17129 | D4: =SUMIFS('Общий Объём работ'!C:C,'Общий Объём работ'!A:A,A4) -> 13535 | E4: =C4-D4 -> 3594 | F4: =D4/C4 -> 0.7901804 | G4: =E4/C4 -> 0.2098196
A5: Каб.констр.(лоток) | B5: м | C5: 1494 | D5: =SUMIFS('Общий Объём работ'!C:C,'Общий Объём работ'!A:A,A5) -> 1557.2 | E5: =C5-D5 -> -63.2 | F5: =D5/C5 -> 1.0423025 | G5: =E5/C5 -> -0.042302544
A6: Светильники | B6: шт | C6: 315 | D6: =SUMIFS('Общий Объём работ'!C:C,'Общий Объём работ'!A:A,A6) -> 274 | E6: =C6-D6 -> 41 | F6: =D6/C6 -> 0.86984127 | G6: =E6/C6 -> 0.13015873
A7: Заземление | B7: м | C7: 2558 | D7: =SUMIFS('Общий Объём работ'!C:C,'Общий Объём работ'!A:A,A7) -> 2585 | E7: =C7-D7 -> -27 | F7: =D7/C7 -> 1.0105551 | G7: =E7/C7 -> -0.010555121
A8: Выключатели /разетки | B8: шт | C8: =8+31+5+63+16+52 -> 175 | D8: =SUMIFS('Общий Объём работ'!C:C,'Общий Объём работ'!A:A,A8) -> 204 | E8: =C8-D8 -> -29 | F8: =D8/C8 -> 1.1657143 | G8: =E8/C8 -> -0.16571429
A10: 406/2 | B10: ед.изм. | C10: Заложено | D10: Выполнено | E10: Остаток | F10: % выполненияя | G10: % осталось
A11: Оборудование | B11: шт | C11: 30 | D11: =SUMIFS('Общий Объём работ'!D:D,'Общий Объём работ'!A:A,A11) -> 16 | E11: =C11-D11 -> 14 | F11: =D11/C11 -> 0.53333333 | G11: =E11/C11 -> 0.46666667
A12: Кабель | B12: м | C12: 17129 | D12: =SUMIFS('Общий Объём работ'!D:D,'Общий Объём работ'!A:A,A12) -> 2586.5 | E12: =C12-D12 -> 14542.5 | F12: =D12/C12 -> 0.15100123 | G12: =E12/C12 -> 0.84899877
A13: Каб.констр.(лоток) | B13: м | C13: 1494 | D13: =SUMIFS('Общий Объём работ'!D:D,'Общий Объём работ'!A:A,A13) -> 1025.7 | E13: =C13-D13 -> 468.3 | F13: =D13/C13 -> 0.68654618 | G13: =E13/C13 -> 0.31345382
A14: Светильники | B14: шт | C14: 315 | D14: =SUMIFS('Общий Объём работ'!D:D,'Общий Объём работ'!A:A,A14) -> 192 | E14: =C14-D14 -> 123 | F14: =D14/C14 -> 0.60952381 | G14: =E14/C14 -> 0.39047619
A15: Заземление | B15: м | C15: 2558 | D15: =SUMIFS('Общий Объём работ'!D:D,'Общий Объём работ'!A:A,A15) -> 1174 | E15: =C15-D15 -> 1384 | F15: =D15/C15 -> 0.45895231 | G15: =E15/C15 -> 0.54104769
A16: Выключатели /разетки | B16: шт | C16: =8+31+5+63+16+52 -> 175 | D16: =SUMIFS('Общий Объём работ'!D:D,'Общий Объём работ'!A:A,A16) -> 0 | E16: =C16-D16 -> 175 | F16: =D16/C16 -> 0 | G16: =E16/C16 -> 1
